Workbook

Sheet enriched_logs
A1: timestamp | B1: interface_in | C1: mac | D1: src_ip | E1: dst_ip | F1: length | G1: tos | H1: prec | I1: ttl | J1: id | K1: proto | L1: src_port | M1: dst_port | N1: window | O1: res | P1: urgp | Q1: continent | R1: country | S1: asn | T1: as_name | U1: as_domain | X1: Time | Z1: Row Labels | AA1: Count of Hours (Time)
A2: 2025-09-06T15:34:54.763279+00:00 | B2: eth0 | C2: 32:cc:1f:83:84:fc:fe:00:00:00:01:01:08:00 | D2: 79.174.24.18 | E2: 157.245.90.47 | F2: 52 | G2: 0x00 | H2: 0x00 | I2: 51 | J2: 26015 | K2: UDP | L2: 58173 | M2: w | N2: N/A | O2: N/A | P2: N/A | Q2: Europe | R2: Albania | S2: AS210125 | T2: PRIAM NET Sh.p.k. | U2: priamnet.al | X2: =DATEVALUE(LEFT(A2,10)) + TIMEVALUE(MID(A2,12,8)) -> 45906.649 | Z2: <9/3/25 | AA2: 1
A3: 2025-09-03T18:37:34.714295+00:00 | B3: eth0 | C3: 32:cc:1f:83:84:fc:fe:00:00:00:01:01:08:00 | D3: 45.230.66.107 | E3: 157.245.90.47 | F3: 60 | G3: 0x00 | H3: 0x00 | I3: 48 | J3: 23973 | K3: TCP | L3: 10809 | M3: 8081 | N3: 28800 | O3: 0x00 | P3: 0 | Q3: South America | R3: Argentina | S3: AS266702 | T3: MEGALINK S.R.L. | U3: ultrafibra.com.ar | X3: =DATEVALUE(LEFT(A3,10)) + TIMEVALUE(MID(A3,12,8)) -> 45903.776 | Z3: 00 | AA3: 540
A4: 2025-09-03T20:45:34.560453+00:00 | B4: eth0 | C4: 32:cc:1f:83:84:fc:fe:00:00:00:01:01:08:00 | D4: 134.199.148.83 | E4: 157.245.90.47 | F4: 70 | G4: 0x00 | H4: 0x00 | I4: 17 | J4: 40437 | K4: UDP | L4: 7551 | M4: 53 | N4: N/A | O4: N/A | P4: N/A | Q4: Oceania | R4: Australia | S4: AS14061 | T4: DigitalOcean, LLC | U4: digitalocean.com | X4: =DATEVALUE(LEFT(A4,10)) + TIMEVALUE(MID(A4,12,8)) -> 45903.865 | Z4: 01 | AA4: 540
A5: 2025-09-03T20:46:17.684330+00:00 | B5: eth0 | C5: 32:cc:1f:83:84:fc:fe:00:00:00:01:01:08:00 | D5: 134.199.148.83 | E5: 157.245.90.47 | F5: 70 | G5: 0x00 | H5: 0x00 | I5: 12 | J5: 40437 | K5: UDP | L5: 7551 | M5: 53 | N5: N/A | O5: N/A | P5: N/A | Q5: Oceania | R5: Australia | S5: AS14061 | T5: DigitalOcean, LLC | U5: digitalocean.com | X5: =DATEVALUE(LEFT(A5,10)) + TIMEVALUE(MID(A5,12,8)) -> 45903.865 | Z5: 02 | AA5: 540
A6: 2025-09-03T20:46:35.215152+00:00 | B6: eth0 | C6: 32:cc:1f:83:84:fc:fe:00:00:00:01:01:08:00 | D6: 134.199.148.83 | E6: 157.245.90.47 | F6: 70 | G6: 0x00 | H6: 0x00 | I6: 10 | J6: 40437 | K6: UDP | L6: 7551 | M6: 53 | N6: N/A | O6: N/A | P6: N/A | Q6: Oceania | R6: Australia | S6: AS14061 | T6: DigitalOcean, LLC | U6: digitalocean.com | X6: =DATEVALUE(LEFT(A6,10)) + TIMEVALUE(MID(A6,12,8)) -> 45903.866 | Z6: 03 | AA6: 541
A7: 2025-09-03T23:16:16.206069+00:00 | B7: eth0 | C7: 32:cc:1f:83:84:fc:fe:00:00:00:01:01:08:00 | D7: 13.211.166.199 | E7: 157.245.90.47 | F7: 79 | G7: 0x00 | H7: 0x00 | I7: 113 | J7: 18637 | K7: UDP | L7: 56074 | M7: 53 | N7: N/A | O7: N/A | P7: N/A | Q7: Oceania | R7: Australia | S7: AS16509 | T7: Amazon.com, Inc. | U7: amazon.com | X7: =DATEVALUE(LEFT(A7,10)) + TIMEVALUE(MID(A7,12,8)) -> 45903.97 | Z7: 04 | AA7: 542
A8: 2025-09-04T03:05:42.017815+00:00 | B8: eth0 | C8: 32:cc:1f:83:84:fc:fe:00:00:00:01:01:08:00 | D8: 170.64.194.116 | E8: 157.245.90.47 | F8: 52 | G8: 0x00 | H8: 0x00 | I8: 54 | J8: 50083 | K8: TCP | L8: 52677 | M8: 3261 | N8: 65280 | O8: 0x00 | P8: 0 | Q8: Oceania | R8: Australia | S8: AS14061 | T8: DigitalOcean, LLC | U8: digitalocean.com | X8: =DATEVALUE(LEFT(A8,10)) + TIMEVALUE(MID(A8,12,8)) -> 45904.129 | Z8: 05 | AA8: 540
A9: 2025-09-04T19:32:11.296579+00:00 | B9: eth0 | C9: 32:cc:1f:83:84:fc:fe:00:00:00:01:01:08:00 | D9: 134.199.160.14 | E9: 157.245.90.47 | F9: 44 | G9: 0x00 | H9: 0x00 | I9: 245 | J9: 54321 | K9: TCP | L9: 35264 | M9: 8080 | N9: 65535 | O9: 0x00 | P9: 0 | Q9: Oceania | R9: Australia | S9: AS14061 | T9: DigitalOcean, LLC | U9: digitalocean.com | X9: =DATEVALUE(LEFT(A9,10)) + TIMEVALUE(MID(A9,12,8)) -> 45904.814 | Z9: 06 | AA9: 540
A10: 2025-09-04T21:28:31.424187+00:00 | B10: eth0 | C10: 32:cc:1f:83:84:fc:fe:00:00:00:01:01:08:00 | D10: 35.244.123.170 | E10: 157.245.90.47 | F10: 40 | G10: 0x00 | H10: 0x00 | I10: 247 | J10: 22724 | K10: TCP | L10: 45432 | M10: 9306 | N10: 1024 | O10: 0x00 | P10: 0 | Q10: Oceania | R10: Australia | S10: AS396982 | T10: Google LLC | U10: google.com | X10: =DATEVALUE(LEFT(A10,10)) + TIMEVALUE(MID(A10,12,8)) -> 45904.895 | Z10: 07 | AA10: 541
A11: 2025-09-04T23:17:31.071391+00:00 | B11: eth0 | C11: 32:cc:1f:83:84:fc:fe:00:00:00:01:01:08:00 | D11: 13.211.12.164 | E11: 157.245.90.47 | F11: 71 | G11: 0x00 | H11: 0x00 | I11: 113 | J11: 48172 | K11: UDP | L11: 56228 | M11: 53 | N11: N/A | O11: N/A | P11: N/A | Q11: Oceania | R11: Australia | S11: AS16509 | T11: Amazon.com, Inc. | U11: amazon.com | X11: =DATEVALUE(LEFT(A11,10)) + TIMEVALUE(MID(A11,12,8)) -> 45904.97 | Z11: 08 | AA11: 539
A12: 2025-09-05T03:41:45.744585+00:00 | B12: eth0 | C12: 32:cc:1f:83:84:fc:fe:00:00:00:01:01:08:00 | D12: 3.27.8.154 | E12: 157.245.90.47 | F12: 60 | G12: 0x00 | H12: 0x00 | I12: 54 | J12: 52335 | K12: TCP | L12: 59872 | M12: 30303 | N12: 26883 | O12: 0x00 | P12: 0 | Q12: Oceania | R12: Australia | S12: AS16509 | T12: Amazon.com, Inc. | U12: amazon.com | X12: =DATEVALUE(LEFT(A12,10)) + TIMEVALUE(MID(A12,12,8)) -> 45905.154 | Z12: 09 | AA12: 540
A13: 2025-09-05T07:05:38.393143+00:00 | B13: eth0 | C13: 32:cc:1f:83:84:fc:fe:00:00:00:01:01:08:00 | D13: 134.199.148.83 | E13: 157.245.90.47 | F13: 44 | G13: 0x00 | H13: 0x00 | I13: 8 | J13: 0 | K13: TCP | L13: 40437 | M13: 443 | N13: 65535 | O13: 0x00 | P13: 0 | Q13: Oceania | R13: Australia | S13: AS14061 | T13: DigitalOcean, LLC | U13: digitalocean.com | X13: =DATEVALUE(LEFT(A13,10)) + TIMEVALUE(MID(A13,12,8)) -> 45905.296 | Z13: 10 | AA13: 540
A14: 2025-09-05T07:06:18.778836+00:00 | B14: eth0 | C14: 32:cc:1f:83:84:fc:fe:00:00:00:01:01:08:00 | D14: 134.199.148.83 | E14: 157.245.90.47 | F14: 44 | G14: 0x00 | H14: 0x00 | I14: 5 | J14: 0 | K14: TCP | L14: 40437 | M14: 443 | N14: 65535 | O14: 0x00 | P14: 0 | Q14: Oceania | R14: Australia | S14: AS14061 | T14: DigitalOcean, LLC | U14: digitalocean.com | X14: =DATEVALUE(LEFT(A14,10)) + TIMEVALUE(MID(A14,12,8)) -> 45905.296 | Z14: 11 | AA14: 540
A15: 2025-09-05T21:05:57.701302+00:00 | B15: eth0 | C15: 32:cc:1f:83:84:fc:fe:00:00:00:01:01:08:00 | D15: 120.157.63.151 | E15: 157.245.90.47 | F15: 60 | G15: 0x00 | H15: 0x00 | I15: 42 | J15: 23931 | K15: TCP | L15: 45865 | M15: 23 | N15: 14600 | O15: 0x00 | P15: 0 | Q15: Oceania | R15: Australia | S15: AS1221 | T15: Telstra Limited | U15: telstra.com.au | X15: =DATEVALUE(LEFT(A15,10)) + TIMEVALUE(MID(A15,12,8)) -> 45905.879 | Z15: 12 | AA15: 548
A16: 2025-09-05T23:19:11.209373+00:00 | B16: eth0 | C16: 32:cc:1f:83:84:fc:fe:00:00:00:01:01:08:00 | D16: 3.24.1.219 | E16: 157.245.90.47 | F16: 71 | G16: 0x00 | H16: 0x00 | I16: 113 | J16: 53233 | K16: UDP | L16: 22274 | M16: 53 | N16: N/A | O16: N/A | P16: N/A | Q16: Oceania | R16: Australia | S16: AS16509 | T16: Amazon.com, Inc. | U16: amazon.com | X16: =DATEVALUE(LEFT(A16,10)) + TIMEVALUE(MID(A16,12,8)) -> 45905.972 | Z16: 13 | AA16: 540
A17: 2025-09-05T23:19:31.512798+00:00 | B17: eth0 | C17: 32:cc:1f:83:84:fc:fe:00:00:00:01:01:08:00 | D17: 13.211.12.181 | E17: 157.245.90.47 | F17: 79 | G17: 0x00 | H17: 0x00 | I17: 113 | J17: 15211 | K17: UDP | L17: 43091 | M17: 53 | N17: N/A | O17: N/A | P17: N/A | Q17: Oceania | R17: Australia | S17: AS16509 | T17: Amazon.com, Inc. | U17: amazon.com | X17: =DATEVALUE(LEFT(A17,10)) + TIMEVALUE(MID(A17,12,8)) -> 45905.972 | Z17: 14 | AA17: 595
A18: 2025-09-05T23:19:52.386579+00:00 | B18: eth0 | C18: 32:cc:1f:83:84:fc:fe:00:00:00:01:01:08:00 | D18: 3.24.1.213 | E18: 157.245.90.47 | F18: 79 | G18: 0x00 | H18: 0x00 | I18: 113 | J18: 51923 | K18: UDP | L18: 12019 | M18: 53 | N18: N/A | O18: N/A | P18: N/A | Q18: Oceania | R18: Australia | S18: AS16509 | T18: Amazon.com, Inc. | U18: amazon.com | X18: =DATEVALUE(LEFT(A18,10)) + TIMEVALUE(MID(A18,12,8)) -> 45905.972 | Z18: 15 | AA18: 713
A19: 2025-09-06T09:49:17.344267+00:00 | B19: eth0 | C19: 32:cc:1f:83:84:fc:fe:00:00:00:01:01:08:00 | D19: 209.38.89.31 | E19: 157.245.90.47 | F19: 44 | G19: 0x00 | H19: 0x00 | I19: 245 | J19: 54321 | K19: TCP | L19: 46189 | M19: 8000 | N19: 65535 | O19: 0x00 | P19: 0 | Q19: Oceania | R19: Australia | S19: AS14061 | T19: DigitalOcean, LLC | U19: digitalocean.com | X19: =DATEVALUE(LEFT(A19,10)) + TIMEVALUE(MID(A19,12,8)) -> 45906.409 | Z19: 16 | AA19: 720
A20: 2025-09-06T14:31:36.699707+00:00 | B20: eth0 | C20: 32:cc:1f:83:84:fc:fe:00:00:00:01:01:08:00 | D20: 169.224.227.132 | E20: 157.245.90.47 | F20: 40 | G20: 0x00 | H20: 0x00 | I20: 237 | J20: 56227 | K20: TCP | L20: 41363 | M20: 1234 | N20: 1024 | O20: 0x00 | P20: 0 | Q20: Oceania | R20: Australia | S20: AS31898 | T20: Oracle Corporation | U20: oracle.com | X20: =DATEVALUE(LEFT(A20,10)) + TIMEVALUE(MID(A20,12,8)) -> 45906.605 | Z20: 17 | AA20: 720
A21: 2025-09-04T04:23:22.360628+00:00 | B21: eth0 | C21: 32:cc:1f:83:84:fc:fe:00:00:00:01:01:08:00 | D21: 195.245.225.238 | E21: 157.245.90.47 | F21: 60 | G21: 0x00 | H21: 0x00 | I21: 53 | J21: 38875 | K21: TCP | L21: 2733 | M21: 30303 | N21: 64240 | O21: 0x00 | P21: 0 | Q21: Europe | R21: Austria | S21: AS51350 | T21: Fachhochschule Technikum Wien | U21: technikum-wien.at | X21: =DATEVALUE(LEFT(A21,10)) + TIMEVALUE(MID(A21,12,8)) -> 45904.183 | Z21: 18 | AA21: 720
A22: 2025-09-04T17:10:11.777104+00:00 | B22: eth0 | C22: 32:cc:1f:83:84:fc:fe:00:00:00:01:01:08:00 | D22: 195.245.225.238 | E22: 157.245.90.47 | F22: 60 | G22: 0x00 | H22: 0x00 | I22: 53 | J22: 46790 | K22: TCP | L22: 47859 | M22: 30303 | N22: 64240 | O22: 0x00 | P22: 0 | Q22: Europe | R22: Austria | S22: AS51350 | T22: Fachhochschule Technikum Wien | U22: technikum-wien.at | X22: =DATEVALUE(LEFT(A22,10)) + TIMEVALUE(MID(A22,12,8)) -> 45904.715 | Z22: 19 | AA22: 720
A23: 2025-09-05T01:48:52.761091+00:00 | B23: eth0 | C23: 32:cc:1f:83:84:fc:fe:00:00:00:01:01:08:00 | D23: 195.245.225.238 | E23: 157.245.90.47 | F23: 60 | G23: 0x00 | H23: 0x00 | I23: 53 | J23: 62646 | K23: TCP | L23: 46367 | M23: 30303 | N23: 64240 | O23: 0x00 | P23: 0 | Q23: Europe | R23: Austria | S23: AS51350 | T23: Fachhochschule Technikum Wien | U23: technikum-wien.at | X23: =DATEVALUE(LEFT(A23,10)) + TIMEVALUE(MID(A23,12,8)) -> 45905.076 | Z23: 20 | AA23: 708
A24: 2025-09-05T19:23:16.562173+00:00 | B24: eth0 | C24: 32:cc:1f:83:84:fc:fe:00:00:00:01:01:08:00 | D24: 195.245.225.238 | E24: 157.245.90.47 | F24: 60 | G24: 0x00 | H24: 0x00 | I24: 53 | J24: 3047 | K24: TCP | L24: 26436 | M24: 30303 | N24: 64240 | O24: 0x00 | P24: 0 | Q24: Europe | R24: Austria | S24: AS51350 | T24: Fachhochschule Technikum Wien | U24: technikum-wien.at | X24: =DATEVALUE(LEFT(A24,10)) + TIMEVALUE(MID(A24,12,8)) -> 45905.808 | Z24: 21 | AA24: 539
A25: 2025-09-06T03:58:18.913610+00:00 | B25: eth0 | C25: 32:cc:1f:83:84:fc:fe:00:00:00:01:01:08:00 | D25: 163.47.37.134 | E25: 157.245.90.47 | F25: 40 | G25: 0x00 | H25: 0x00 | I25: 235 | J25: 21100 | K25: TCP | L25: 60000 | M25: 41622 | N25: 1024 | O25: 0x00 | P25: 0 | Q25: Asia | R25: Bangladesh | S25: AS63961 | T25: Bangladesh Research and Education Network (BdREN) | U25: bdren.net.bd | X25: =DATEVALUE(LEFT(A25,10)) + TIMEVALUE(MID(A25,12,8)) -> 45906.165 | Z25: 22 | AA25: 541
A26: 2025-09-03T16:32:15.242145+00:00 | B26: eth0 | C26: 32:cc:1f:83:84:fc:fe:00:00:00:01:01:08:00 | D26: 77.90.185.47 | E26: 157.245.90.47 | F26: 44 | G26: 0x00 | H26: 0x00 | I26: 243 | J26: 54994 | K26: TCP | L26: 41966 | M26: 5433 | N26: 1025 | O26: 0x00 | P26: 0 | Q26: Europe | R26: Belarus | S26: AS215476 | T26: Inside Network LTD | U26: insidenetwork.info | X26: =DATEVALUE(LEFT(A26,10)) + TIMEVALUE(MID(A26,12,8)) -> 45903.689 | Z26: 23 | AA26: 530
A27: 2025-09-04T19:16:53.480082+00:00 | B27: eth0 | C27: 32:cc:1f:83:84:fc:fe:00:00:00:01:01:08:00 | D27: 77.90.185.47 | E27: 157.245.90.47 | F27: 44 | G27: 0x00 | H27: 0x00 | I27: 242 | J27: 35227 | K27: TCP | L27: 53702 | M27: 55432 | N27: 1025 | O27: 0x00 | P27: 0 | Q27: Europe | R27: Belarus | S27: AS215476 | T27: Inside Network LTD | U27: insidenetwork.info | X27: =DATEVALUE(LEFT(A27,10)) + TIMEVALUE(MID(A27,12,8)) -> 45904.803 | Z27: Grand Total | AA27: 14078
A28: 2025-09-06T02:38:37.780092+00:00 | B28: eth0 | C28: 32:cc:1f:83:84:fc:fe:00:00:00:01:01:08:00 | D28: 77.90.185.47 | E28: 157.245.90.47 | F28: 44 | G28: 0x00 | H28: 0x00 | I28: 241 | J28: 36075 | K28: TCP | L28: 49853 | M28: 5433 | N28: 1025 | O28: 0x00 | P28: 0 | Q28: Europe | R28: Belarus | S28: AS215476 | T28: Inside Network LTD | U28: insidenetwork.info | X28: =DATEVALUE(LEFT(A28,10)) + TIMEVALUE(MID(A28,12,8)) -> 45906.11
A29: 2025-09-06T05:09:31.590227+00:00 | B29: eth0 | C29: 32:cc:1f:83:84:fc:fe:00:00:00:01:01:08:00 | D29: 77.90.185.47 | E29: 157.245.90.47 | F29: 44 | G29: 0x00 | H29: 0x00 | I29: 243 | J29: 43399 | K29: TCP | L29: 53427 | M29: 15432 | N29: 1025 | O29: 0x00 | P29: 0 | Q29: Europe | R29: Belarus | S29: AS215476 | T29: Inside Network LTD | U29: insidenetwork.info | X29: =DATEVALUE(LEFT(A29,10)) + TIMEVALUE(MID(A29,12,8)) -> 45906.215
A30: 2025-09-03T17:16:15.488595+00:00 | B30: eth0 | C30: 32:cc:1f:83:84:fc:fe:00:00:00:01:01:08:00 | D30: 34.140.117.233 | E30: 157.245.90.47 | F30: 52 | G30: 0x00 | H30: 0x40 | I30: 122 | J30: 55675 | K30: TCP | L30: 57242 | M30: 80 | N30: 65320 | O30: 0x00 | P30: 0 | Q30: Europe | R30: Belgium | S30: AS396982 | T30: Google LLC | U30: google.com | X30: =DATEVALUE(LEFT(A30,10)) + TIMEVALUE(MID(A30,12,8)) -> 45903.72
A31: 2025-09-03T18:46:03.575558+00:00 | B31: eth0 | C31: 32:cc:1f:83:84:fc:fe:00:00:00:01:01:08:00 | D31: 198.235.24.218 | E31: 157.245.90.47 | F31: 44 | G31: 0x00 | H31: 0x60 | I31: 249 | J31: 54321 | K31: TCP | L31: 52120 | M31: 32569 | N31: 65535 | O31: 0x00 | P31: 0 | Q31: Europe | R31: Belgium | S31: AS396982 | T31: Google LLC | U31: google.com | X31: =DATEVALUE(LEFT(A31,10)) + TIMEVALUE(MID(A31,12,8)) -> 45903.782
A32: 2025-09-03T20:31:55.637980+00:00 | B32: eth0 | C32: 32:cc:1f:83:84:fc:fe:00:00:00:01:01:08:00 | D32: 198.235.24.236 | E32: 157.245.90.47 | F32: 92 | G32: 0x00 | H32: 0x60 | I32: 249 | J32: 54321 | K32: UDP | L32: 50042 | M32: 17185 | N32: N/A | O32: N/A | P32: N/A | Q32: Europe | R32: Belgium | S32: AS396982 | T32: Google LLC | U32: google.com | X32: =DATEVALUE(LEFT(A32,10)) + TIMEVALUE(MID(A32,12,8)) -> 45903.855
A33: 2025-09-04T02:32:41.001131+00:00 | B33: eth0 | C33: 32:cc:1f:83:84:fc:fe:00:00:00:01:01:08:00 | D33: 198.235.24.225 | E33: 157.245.90.47 | F33: 44 | G33: 0x00 | H33: 0x00 | I33: 249 | J33: 54321 | K33: TCP | L33: 53721 | M33: 50805 | N33: 65535 | O33: 0x00 | P33: 0 | Q33: Europe | R33: Belgium | S33: AS396982 | T33: Google LLC | U33: google.com | X33: =DATEVALUE(LEFT(A33,10)) + TIMEVALUE(MID(A33,12,8)) -> 45904.106
A34: 2025-09-04T03:55:01.050663+00:00 | B34: eth0 | C34: 32:cc:1f:83:84:fc:fe:00:00:00:01:01:08:00 | D34: 198.235.24.225 | E34: 157.245.90.47 | F34: 44 | G34: 0x00 | H34: 0x60 | I34: 249 | J34: 54321 | K34: TCP | L34: 55626 | M34: 58603 | N34: 65535 | O34: 0x00 | P34: 0 | Q34: Europe | R34: Belgium | S34: AS396982 | T34: Google LLC | U34: google.com | X34: =DATEVALUE(LEFT(A34,10)) + TIMEVALUE(MID(A34,12,8)) -> 45904.163
A35: 2025-09-04T04:41:20.815875+00:00 | B35: eth0 | C35: 32:cc:1f:83:84:fc:fe:00:00:00:01:01:08:00 | D35: 198.235.24.239 | E35: 157.245.90.47 | F35: 44 | G35: 0x00 | H35: 0x60 | I35: 249 | J35: 54321 | K35: TCP | L35: 49633 | M35: 3975 | N35: 65535 | O35: 0x00 | P35: 0 | Q35: Europe | R35: Belgium | S35: AS396982 | T35: Google LLC | U35: google.com | X35: =DATEVALUE(LEFT(A35,10)) + TIMEVALUE(MID(A35,12,8)) -> 45904.195
A36: 2025-09-04T05:15:40.881627+00:00 | B36: eth0 | C36: 32:cc:1f:83:84:fc:fe:00:00:00:01:01:08:00 | D36: 198.235.24.171 | E36: 157.245.90.47 | F36: 44 | G36: 0x00 | H36: 0x60 | I36: 249 | J36: 54321 | K36: TCP | L36: 57064 | M36: 4444 | N36: 65535 | O36: 0x00 | P36: 0 | Q36: Europe | R36: Belgium | S36: AS396982 | T36: Google LLC | U36: google.com | X36: =DATEVALUE(LEFT(A36,10)) + TIMEVALUE(MID(A36,12,8)) -> 45904.219
A37: 2025-09-04T05:57:45.982219+00:00 | B37: eth0 | C37: 32:cc:1f:83:84:fc:fe:00:00:00:01:01:08:00 | D37: 198.235.24.183 | E37: 157.245.90.47 | F37: 44 | G37: 0x00 | H37: 0x60 | I37: 249 | J37: 54321 | K37: TCP | L37: 56184 | M37: 25789 | N37: 65535 | O37: 0x00 | P37: 0 | Q37: Europe | R37: Belgium | S37: AS396982 | T37: Google LLC | U37: google.com | X37: =DATEVALUE(LEFT(A37,10)) + TIMEVALUE(MID(A37,12,8)) -> 45904.248
A38: 2025-09-04T06:00:41.142996+00:00 | B38: eth0 | C38: 32:cc:1f:83:84:fc:fe:00:00:00:01:01:08:00 | D38: 198.235.24.206 | E38: 157.245.90.47 | F38: 44 | G38: 0x00 | H38: 0x60 | I38: 249 | J38: 54321 | K38: TCP | L38: 54315 | M38: 4026 | N38: 65535 | O38: 0x00 | P38: 0 | Q38: Europe | R38: Belgium | S38: AS396982 | T38: Google LLC | U38: google.com | X38: =DATEVALUE(LEFT(A38,10)) + TIMEVALUE(MID(A38,12,8)) -> 45904.25
A39: 2025-09-04T07:31:21.853836+00:00 | B39: eth0 | C39: 32:cc:1f:83:84:fc:fe:00:00:00:01:01:08:00 | D39: 198.235.24.232 | E39: 157.245.90.47 | F39: 44 | G39: 0x00 | H39: 0x60 | I39: 249 | J39: 54321 | K39: TCP | L39: 57117 | M39: 1024 | N39: 65535 | O39: 0x00 | P39: 0 | Q39: Europe | R39: Belgium | S39: AS396982 | T39: Google LLC | U39: google.com | X39: =DATEVALUE(LEFT(A39,10)) + TIMEVALUE(MID(A39,12,8)) -> 45904.313
A40: 2025-09-04T07:36:41.087338+00:00 | B40: eth0 | C40: 32:cc:1f:83:84:fc:fe:00:00:00:01:01:08:00 | D40: 198.235.24.253 | E40: 157.245.90.47 | F40: 44 | G40: 0x00 | H40: 0x00 | I40: 249 | J40: 54321 | K40: TCP | L40: 52996 | M40: 4024 | N40: 65535 | O40: 0x00 | P40: 0 | Q40: Europe | R40: Belgium | S40: AS396982 | T40: Google LLC | U40: google.com | X40: =DATEVALUE(LEFT(A40,10)) + TIMEVALUE(MID(A40,12,8)) -> 45904.317
...

Sheet Sheet1
B2: {=_xlfn.UNIQUE(enriched_logs!R2:R14078)} -> Albania | C2: {=COUNTIF(enriched_logs!R$2:R$14078,_xlfn.ANCHORARRAY( B2))} -> 1 | E2: {=_xlfn._xlws.SORT(_xlfn.HSTACK(_xlfn.UNIQUE(enriched_logs!R2:R14078), COUNTIF(enriched_logs!R$2:R$14078, _xlfn.UNIQUE(enriched_logs!R2:R14078))), 2, -1)} -> United States | F2: 3493 | H2: {=_xlfn._xlws.SORT(_xlfn.HSTACK(_xlfn.UNIQUE(enriched_logs!T2:T14078), COUNTIF(enriched_logs!T$2:T$14078, _xlfn.UNIQUE(enriched_logs!T2:T14078))), 2, -1)} -> Amazon.com, Inc. | I2: 6995 | K2: {=_xlfn._xlws.SORT(_xlfn.HSTACK(_xlfn.UNIQUE(enriched_logs!U2:U14078), COUNTIF(enriched_logs!U$2:U$14078, _xlfn.UNIQUE(enriched_logs!U2:U14078))), 2, -1)} -> amazon.com | L2: 6995 | N2: {=_xlfn._xlws.SORT(_xlfn.HSTACK(_xlfn.UNIQUE(enriched_logs!M2:M14078), COUNTIF(enriched_logs!M$2:M$14078, _xlfn.UNIQUE(enriched_logs!M2:M14078))), 2, -1)} -> 30303 | O2: 7426 | P2: Ethereum Client Port | R2: {=_xlfn._xlws.SORT(_xlfn.HSTACK(_xlfn.UNIQUE(enriched_logs!D2:D14078), COUNTIF(enriched_logs!D$2:D$14078, _xlfn.UNIQUE(enriched_logs!D2:D14078))), 2, -1)} -> 18.175.136.85 | S2: 966
B3: Argentina | C3: 1 | E3: Germany | F3: 3163 | H3: cheapy.host LLC | I3: 986 | K3: cheapy.host | L3: 986 | N3: 53 | O3: 571 | P3: DNS Port (DDoS) | R3: 52.213.121.14 | S3: 946
B4: Australia | C4: 17 | E4: The Netherlands | F4: 1842 | H4: Google LLC | I4: 706 | K4: google.com | L4: 706 | N4: 23 | O4: 156 | P4: Telnet port (uname+pass brutef) | R4: 18.162.120.131 | S4: 791
B5: Austria | C5: 4 | E5: Ireland | F5: 1557 | H5: OVH SAS | I5: 606 | K5: ovhcloud.com | L5: 606 | N5: 8080 | O5: 65 | P5: HTTP alt / DDoS, CORS | R5: 3.70.55.65 | S5: 746
B6: Bangladesh | C6: 1 | E6: United Kingdom | F6: 1264 | H6: TELCHAK GOLD VENTURES (PRIVATE) LIMITED | I6: 533 | K6: telchakgoldventuresprivatelimitedinternational.xyz | L6: 533 | N6: 8728 | O6: 58 | P6: Mikrotik router vuln., botnet | R6: 54.234.104.125 | S6: 705
B7: Belarus | C7: 4 | E7: Hong Kong | F7: 921 | H7: Akamai Connected Cloud | I7: 509 | K7: linode.com | L7: 509 | N7: 37215 | O7: 57 | P7: Huawei router, DDoS capture | R7: 63.176.22.69 | S7: 696
B8: Belgium | C8: 44 | E8: Japan | F8: 613 | H8: Censys, Inc. | I8: 491 | K8: censys.io | L8: 491 | N8: 5900 | O8: 48 | P8: VNC protocol, UPnP req. vuln | R8: 3.68.53.133 | S8: 690
B9: Brazil | C9: 50 | E9: France | F9: 196 | H9: DigitalOcean, LLC | I9: 285 | K9: digitalocean.com | L9: 285 | N9: 80 | O9: 41 | P9: HTTP port | R9: 54.78.131.68 | S9: 608
B10: Bulgaria | C10: 79 | E10: China | F10: 98 | H10: UCLOUD INFORMATION TECHNOLOGY (HK) LIMITED | I10: 210 | K10: N/A | L10: 218 | N10: 3128 | O10: 32 | P10: Proxy server (squid), encr. vuln | R10: 135.148.168.151 | S10: 579
B11: Canada | C11: 79 | E11: Finland | F11: 95 | H11: IP Volume inc | I11: 191 | K11: ucloud.cn | L11: 210 | N11: 443 | O11: 30 | P11: HTTPS port | R11: 3.115.23.90 | S11: 516
B12: Chile | C12: 1 | E12: Bulgaria | F12: 79 | H12: ONYPHE SAS | I12: 170 | K12: ipvolume.net | L12: 191 | N12: 8443 | O12: 27 | R12: 63.176.157.198 | S12: 138
B13: China | C13: 98 | E13: Canada | F13: 79 | H13: Microsoft Corporation | I13: 164 | K13: onyphe.io | L13: 170 | N13: 2222 | O13: 26 | R13: 196.251.69.91 | S13: 109
B14: Colombia | C14: 1 | E14: Singapore | F14: 78 | H14: Hurricane Electric LLC | I14: 156 | K14: microsoft.com | L14: 164 | N14: 4145 | O14: 24 | R14: 196.251.83.215 | S14: 107
B15: Croatia | C15: 6 | E15: Russia | F15: 69 | H15: Nybula LLC | I15: 137 | K15: he.net | L15: 156 | N15: 8888 | O15: 23 | R15: 196.251.87.74 | S15: 103
B16: Czechia | C16: 2 | E16: Taiwan | F16: 58 | H16: SKYNET NETWORK LTD | I16: 109 | K16: nybula.com | L16: 137 | N16: 3389 | O16: 23 | R16: 206.123.145.4 | S16: 100
B17: Denmark | C17: 1 | E17: India | F17: 54 | H17: Interserver, Inc | I17: 109 | K17: interserver.net | L17: 109 | N17: 5678 | O17: 23 | R17: 206.123.145.21 | S17: 94
B18: Ecuador | C18: 1 | E18: Brazil | F18: 50 | H18: Alibaba (US) Technology Co., Ltd. | I18: 88 | K18: alibabagroup.com | L18: 108 | N18: 6379 | O18: 22 | R18: 196.251.69.116 | S18: 86
B19: Finland | C19: 95 | E19: Belgium | F19: 44 | H19: Railnet LLC | I19: 86 | K19: virtualine.org | L19: 86 | N19: 5060 | O19: 21 | R19: 206.123.145.25 | S19: 81
B20: France | C20: 196 | E20: South Korea | F20: 35 | H20: Driftnet Ltd | I20: 79 | K20: driftnet.io | L20: 79 | N20: 123 | O20: 18 | R20: 196.251.72.177 | S20: 81
B21: Georgia | C21: 4 | E21: Switzerland | F21: 29 | H21: Cloudflare, Inc. | I21: 78 | K21: cloudflare.com | L21: 78 | N21: 1080 | O21: 18 | R21: 206.123.145.234 | S21: 77
B22: Germany | C22: 3163 | E22: Sweden | F22: 26 | H22: Pfcloud UG | I22: 78 | K22: pfcloud.io | L22: 78 | N22: 9922 | O22: 18 | R22: 206.123.145.37 | S22: 75
B23: Hong Kong | C23: 921 | E23: Nigeria | F23: 23 | H23: FOP Dmytro Nedilskyi | I23: 76 | K23: agotoz.com | L23: 75 | N23: 4150 | O23: 18 | R23: 206.123.145.35 | S23: 66
... B61: Vietnam | C61: 12 | E61: Trinidad and Tobago | F61: 1 | H61: Kamatera, Inc. | I61: 10 | K61: galeonllc.ru | L61: 10 | N61: 8083 | O61: 10 | R61: 45.142.193.177 | S61: 14
H62: CDS Global Cloud Co., Ltd | I62: 10 | K62: unmanaged.uk | L62: 9 | N62: 20087 | O62: 10 | R62: 92.63.197.210 | S62: 14
H63: PJSC Rostelecom | I63: 10 | K63: hinet.net | L63: 9 | N63: 60001 | O63: 10 | R63: 196.251.66.71 | S63: 14
H64: Galeon LLC | I64: 10 | K64: scloud.sg | L64: 9 | N64: 1723 | O64: 9 | R64: 88.210.63.55 | S64: 14
H65: Tencent Building, Kejizhongyi Avenue | I65: 9 | K65: chinatelecom.cn | L65: 8 | N65: 4443 | O65: 9 | R65: 109.205.213.124 | S65: 14
H66: UNMANAGED LTD | I66: 9 | K66: opendns.com | L66: 8 | N66: 11434 | O66: 9 | R66: 167.94.146.36 | S66: 13
H67: Data Communication Business Group | I67: 9 | K67: init7.net | L67: 8 | N67: 20019 | O67: 9 | R67: 196.251.116.162 | S67: 13
H68: Scloud Pte Ltd | I68: 9 | K68: koddos.net | L68: 8 | N68: 20014 | O68: 9 | R68: 196.251.71.226 | S68: 13
H69: Cisco OpenDNS, LLC | I69: 8 | K69: colocrossing.com | L69: 8 | N69: 20171 | O69: 9 | R69: 45.142.193.49 | S69: 13
H70: Init7 (Switzerland) Ltd. | I70: 8 | K70: hetzner.de | L70: 7 | N70: 88 | O70: 9 | R70: 196.251.86.195 | S70: 13
H71: Amarutu Technology Ltd | I71: 8 | K71: i3d.net | L71: 7 | N71: 2022 | O71: 9 | R71: 109.205.213.115 | S71: 13
H72: HostPapa | I72: 8 | K72: lumen.com | L72: 7 | N72: 20205 | O72: 9 | R72: 109.205.213.8 | S72: 13
H73: Hetzner Online GmbH | I73: 7 | K73: as49870.net | L73: 7 | N73: 11211 | O73: 9 | R73: 79.124.49.194 | S73: 12
... H260: FASTNET DATA INC | I260: 1 | K260: fpt.vn | L260: 1 | N260: 5005 | O260: 4 | R260: 193.163.125.22 | S260: 4
H261: NTT America, Inc. | I261: 1 | N261: 16411 | O261: 4 | R261: 193.163.125.24 | S261: 4
H262: tzulo, inc. | I262: 1 | N262: 3324 | O262: 4 | R262: 165.227.226.99 | S262: 4
H263: Comcast Cable Communications, LLC | I263: 1 | N263: 8093 | O263: 4 | R263: 43.130.72.177 | S263: 4
H264: Turing Group Limited | I264: 1 | N264: 48852 | O264: 4 | R264: 162.142.125.143 | S264: 4
...
